Workbook

Sheet Overall Tracker
A1: SAMUH — Overall Production Tracker (Plant-wise Rollup)
A2: Plant / Location | B2: CMU Name | C2: No. of SKUs | D2: Month Plan (Ton) | E2: Total Production (Ton) | F2: Total Production (Case) | G2: Achievement % | H2: Remaining (Ton)
A3: Lucknow | B3: VEETADAY INDUSTRIES PRIVATE LIMITED | C3: =COUNTIF('Plant-wise Tracker'!$E$5:$E$125,A3) -> 21 | D3: =SUMIFS('Plant-wise Tracker'!$L$5:$L$125,'Plant-wise Tracker'!$E$5:$E$125,A3) -> 0 | E3: =SUMIFS('Plant-wise Tracker'!$AR$5:$AR$125,'Plant-wise Tracker'!$E$5:$E$125,A3) -> 0 | F3: =SUMIFS('Plant-wise Tracker'!$AQ$5:$AQ$125,'Plant-wise Tracker'!$E$5:$E$125,A3) -> 0 | G3: =IFERROR(E3/D3,0) -> 0 | H3: =SUMIFS('Plant-wise Tracker'!$AT$5:$AT$125,'Plant-wise Tracker'!$E$5:$E$125,A3) -> 0
A4: Rudrapur | B4: SWG | C4: =COUNTIF('Plant-wise Tracker'!$E$5:$E$125,A4) -> 21 | D4: =SUMIFS('Plant-wise Tracker'!$L$5:$L$125,'Plant-wise Tracker'!$E$5:$E$125,A4) -> 0 | E4: =SUMIFS('Plant-wise Tracker'!$AR$5:$AR$125,'Plant-wise Tracker'!$E$5:$E$125,A4) -> 0 | F4: =SUMIFS('Plant-wise Tracker'!$AQ$5:$AQ$125,'Plant-wise Tracker'!$E$5:$E$125,A4) -> 0 | G4: =IFERROR(E4/D4,0) -> 0 | H4: =SUMIFS('Plant-wise Tracker'!$AT$5:$AT$125,'Plant-wise Tracker'!$E$5:$E$125,A4) -> 0
A5: Asansol, West Bengal | B5: STRAIGHT LINE FOOD PRODUCTS PRIVATE LIMITED | C5: =COUNTIF('Plant-wise Tracker'!$E$5:$E$125,A5) -> 21 | D5: =SUMIFS('Plant-wise Tracker'!$L$5:$L$125,'Plant-wise Tracker'!$E$5:$E$125,A5) -> 0 | E5: =SUMIFS('Plant-wise Tracker'!$AR$5:$AR$125,'Plant-wise Tracker'!$E$5:$E$125,A5) -> 0 | F5: =SUMIFS('Plant-wise Tracker'!$AQ$5:$AQ$125,'Plant-wise Tracker'!$E$5:$E$125,A5) -> 0 | G5: =IFERROR(E5/D5,0) -> 0 | H5: =SUMIFS('Plant-wise Tracker'!$AT$5:$AT$125,'Plant-wise Tracker'!$E$5:$E$125,A5) -> 0
A6: Kathua, Jammu | B6: RATTAN OIL MILLS | C6: =COUNTIF('Plant-wise Tracker'!$E$5:$E$125,A6) -> 21 | D6: =SUMIFS('Plant-wise Tracker'!$L$5:$L$125,'Plant-wise Tracker'!$E$5:$E$125,A6) -> 0 | E6: =SUMIFS('Plant-wise Tracker'!$AR$5:$AR$125,'Plant-wise Tracker'!$E$5:$E$125,A6) -> 0 | F6: =SUMIFS('Plant-wise Tracker'!$AQ$5:$AQ$125,'Plant-wise Tracker'!$E$5:$E$125,A6) -> 0 | G6: =IFERROR(E6/D6,0) -> 0 | H6: =SUMIFS('Plant-wise Tracker'!$AT$5:$AT$125,'Plant-wise Tracker'!$E$5:$E$125,A6) -> 0
A7: Kanpur | B7: Meera Baker | C7: =COUNTIF('Plant-wise Tracker'!$E$5:$E$125,A7) -> 2 | D7: =SUMIFS('Plant-wise Tracker'!$L$5:$L$125,'Plant-wise Tracker'!$E$5:$E$125,A7) -> 0 | E7: =SUMIFS('Plant-wise Tracker'!$AR$5:$AR$125,'Plant-wise Tracker'!$E$5:$E$125,A7) -> 0 | F7: =SUMIFS('Plant-wise Tracker'!$AQ$5:$AQ$125,'Plant-wise Tracker'!$E$5:$E$125,A7) -> 0 | G7: =IFERROR(E7/D7,0) -> 0 | H7: =SUMIFS('Plant-wise Tracker'!$AT$5:$AT$125,'Plant-wise Tracker'!$E$5:$E$125,A7) -> 0
A8: Kashipur | B8: DEVARPAN FOODS PRIVATE LIMITED | C8: 2 | E8: =SUMIFS('Plant-wise Tracker'!$AR$5:$AR$125,'Plant-wise Tracker'!$E$5:$E$125,A8) -> 0 | F8: =SUMIFS('Plant-wise Tracker'!$AQ$5:$AQ$125,'Plant-wise Tracker'!$E$5:$E$125,A8) -> 0 | G8: =IFERROR(E8/D8,0) -> 0 | H8: =SUMIFS('Plant-wise Tracker'!$AT$5:$AT$125,'Plant-wise Tracker'!$E$5:$E$125,A8) -> 12
A9: Shubham Enterprises | B9: Saharnpur | C9: =COUNTIF('Plant-wise Tracker'!$E$5:$E$125,A9) -> 2 | D9: =SUMIFS('Plant-wise Tracker'!$L$5:$L$125,'Plant-wise Tracker'!$E$5:$E$125,A9) -> 0 | E9: =SUMIFS('Plant-wise Tracker'!$AR$5:$AR$125,'Plant-wise Tracker'!$E$5:$E$125,A9) -> 0 | F9: =SUMIFS('Plant-wise Tracker'!$AQ$5:$AQ$125,'Plant-wise Tracker'!$E$5:$E$125,A9) -> 0 | G9: =IFERROR(E9/D9,0) -> 0 | H9: =SUMIFS('Plant-wise Tracker'!$AT$5:$AT$125,'Plant-wise Tracker'!$E$5:$E$125,A9) -> 0
A10: Kolkata | B10: BHAGWATI | C10: =COUNTIF('Plant-wise Tracker'!$E$5:$E$125,A10) -> 19 | D10: =SUMIFS('Plant-wise Tracker'!$L$5:$L$125,'Plant-wise Tracker'!$E$5:$E$125,A10) -> 0 | E10: =SUMIFS('Plant-wise Tracker'!$AR$5:$AR$125,'Plant-wise Tracker'!$E$5:$E$125,A10) -> 0 | F10: =SUMIFS('Plant-wise Tracker'!$AQ$5:$AQ$125,'Plant-wise Tracker'!$E$5:$E$125,A10) -> 0 | G10: =IFERROR(E10/D10,0) -> 0 | H10: =SUMIFS('Plant-wise Tracker'!$AT$5:$AT$125,'Plant-wise Tracker'!$E$5:$E$125,A10) -> 0
A11: Punjab | B11: Shri Shyam | C11: =COUNTIF('Plant-wise Tracker'!$E$5:$E$125,A11) -> 2 | D11: =SUMIFS('Plant-wise Tracker'!$L$5:$L$125,'Plant-wise Tracker'!$E$5:$E$125,A11) -> 0 | E11: =SUMIFS('Plant-wise Tracker'!$AR$5:$AR$125,'Plant-wise Tracker'!$E$5:$E$125,A11) -> 0 | F11: =SUMIFS('Plant-wise Tracker'!$AQ$5:$AQ$125,'Plant-wise Tracker'!$E$5:$E$125,A11) -> 0 | G11: =IFERROR(E11/D11,0) -> 0 | H11: =SUMIFS('Plant-wise Tracker'!$AT$5:$AT$125,'Plant-wise Tracker'!$E$5:$E$125,A11) -> 0
A12: GRAND TOTAL | C12: =SUM(C3:C11) -> 111 | D12: =SUM(D3:D11) -> 0 | E12: =SUM(E3:E11) -> 0 | F12: =SUM(F3:F11) -> 0 | G12: =IFERROR(E12/D12,0) -> 0
A15: Category-wise Summary
A16: Category | B16: Month Plan (Ton) | C16: Total Production (Ton) | D16: Achievement %
A17: Biscuits | B17: =SUMIFS('Master Data'!$L$3:$L$113,'Master Data'!$F$3:$F$113,A17) -> 0 | C17: =SUMIFS('Master Data'!$AS$3:$AS$113,'Master Data'!$F$3:$F$113,A17) -> 0 | D17: =IFERROR(C17/B17,0) -> 0
A18: Rusk | B18: =SUMIFS('Master Data'!$L$3:$L$113,'Master Data'!$F$3:$F$113,A18) -> 0 | C18: =SUMIFS('Master Data'!$AS$3:$AS$113,'Master Data'!$F$3:$F$113,A18) -> 0 | D18: =IFERROR(C18/B18,0) -> 0
H21: s
A41: Product-wise Achievement
A42: SKU Code | B42: Product Name | C42: Location | D42: Category | E42: Month Plan (Ton) | F42: Total Production (Ton) | G42: Achievement % | H42: Remaining (Ton)
A43: ='Master Data'!G3 -> ROZ39494 | B43: ='Master Data'!H3 -> Samuh Milky Biscuit 35 g | C43: ='Master Data'!E3 -> Lucknow | D43: ='Master Data'!F3 -> Biscuits | E43: ='Master Data'!L3 -> 0 | F43: ='Master Data'!AS3 -> 0 | G43: =IFERROR('Master Data'!AT3,0) -> 0 | H43: ='Master Data'!AU3 -> 0
A44: ='Master Data'!G4 -> ROZ23739 | B44: ='Master Data'!H4 -> Samuh Beat it! Bite it! Orange Cream Biscuit 35 g | C44: ='Master Data'!E4 -> Lucknow | D44: ='Master Data'!F4 -> Biscuits | E44: ='Master Data'!L4 -> 0 | F44: ='Master Data'!AS4 -> 0 | G44: =IFERROR('Master Data'!AT4,0) -> 0 | H44: ='Master Data'!AU4 -> 0
A45: ='Master Data'!G5 -> ROZ23738 | B45: ='Master Data'!H5 -> Samuh Beat it Bite it Chocolate Cream Biscuit 35 g | C45: ='Master Data'!E5 -> Lucknow | D45: ='Master Data'!F5 -> Biscuits | E45: ='Master Data'!L5 -> 0 | F45: ='Master Data'!AS5 -> 0 | G45: =IFERROR('Master Data'!AT5,0) -> 0 | H45: ='Master Data'!AU5 -> 0
A46: ='Master Data'!G6 -> ROZ23743 | B46: ='Master Data'!H6 -> Samuh Butter Cookies Biscuit 32 g | C46: ='Master Data'!E6 -> Lucknow | D46: ='Master Data'!F6 -> Biscuits | E46: ='Master Data'!L6 -> 0 | F46: ='Master Data'!AS6 -> 0 | G46: =IFERROR('Master Data'!AT6,0) -> 0 | H46: ='Master Data'!AU6 -> 0
A47: ='Master Data'!G7 -> ROZ23740 | B47: ='Master Data'!H7 -> Samuh Zeera Biscuit 35 g | C47: ='Master Data'!E7 -> Lucknow | D47: ='Master Data'!F7 -> Biscuits | E47: ='Master Data'!L7 -> 0 | F47: ='Master Data'!AS7 -> 0 | G47: =IFERROR('Master Data'!AT7,0) -> 0 | H47: ='Master Data'!AU7 -> 0
A48: ='Master Data'!G8 -> ROZ23741 | B48: ='Master Data'!H8 -> Samuh Coconut Cookies Biscuit 35 g | C48: ='Master Data'!E8 -> Lucknow | D48: ='Master Data'!F8 -> Biscuits | E48: ='Master Data'!L8 -> 0 | F48: ='Master Data'!AS8 -> 0 | G48: =IFERROR('Master Data'!AT8,0) -> 0 | H48: ='Master Data'!AU8 -> 0
A49: ='Master Data'!G9 -> ROZ23742 | B49: ='Master Data'!H9 -> Samuh Salty Sweety Biscuit 32 g | C49: ='Master Data'!E9 -> Lucknow | D49: ='Master Data'!F9 -> Biscuits | E49: ='Master Data'!L9 -> 0 | F49: ='Master Data'!AS9 -> 0 | G49: =IFERROR('Master Data'!AT9,0) -> 0 | H49: ='Master Data'!AU9 -> 0
A50: ='Master Data'!G10 -> ROZ36954 | B50: ='Master Data'!H10 -> Samuh Butter Cashew 30 g | C50: ='Master Data'!E10 -> Lucknow | D50: ='Master Data'!F10 -> Biscuits | E50: ='Master Data'!L10 -> 0 | F50: ='Master Data'!AS10 -> 0 | G50: =IFERROR('Master Data'!AT10,0) -> 0 | H50: ='Master Data'!AU10 -> 0
A51: ='Master Data'!G11 -> ROZ36955 | B51: ='Master Data'!H11 -> Samuh Beat it Bite it Chocolate Cream Biscuit 70 g | C51: ='Master Data'!E11 -> Lucknow | D51: ='Master Data'!F11 -> Biscuits | E51: ='Master Data'!L11 -> 0 | F51: ='Master Data'!AS11 -> 0 | G51: =IFERROR('Master Data'!AT11,0) -> 0 | H51: ='Master Data'!AU11 -> 0
A52: ='Master Data'!G12 -> ROZ36956 | B52: ='Master Data'!H12 -> Samuh Beat it! Bite it! Orange Cream Biscuit 70 g | C52: ='Master Data'!E12 -> Lucknow | D52: ='Master Data'!F12 -> Biscuits | E52: ='Master Data'!L12 -> 0 | F52: ='Master Data'!AS12 -> 0 | G52: =IFERROR('Master Data'!AT12,0) -> 0 | H52: ='Master Data'!AU12 -> 0
A53: ='Master Data'!G13 -> ROZ36957 | B53: ='Master Data'!H13 -> Samuh Coconut Cookies Biscuit 70g | C53: ='Master Data'!E13 -> Lucknow | D53: ='Master Data'!F13 -> Biscuits | E53: ='Master Data'!L13 -> 0 | F53: ='Master Data'!AS13 -> 0 | G53: =IFERROR('Master Data'!AT13,0) -> 0 | H53: ='Master Data'!AU13 -> 0
A54: ='Master Data'!G14 -> ROZ39495 | B54: ='Master Data'!H14 -> Samuh Milky Biscuit 70 g | C54: ='Master Data'!E14 -> Lucknow | D54: ='Master Data'!F14 -> Biscuits | E54: ='Master Data'!L14 -> 0 | F54: ='Master Data'!AS14 -> 0 | G54: =IFERROR('Master Data'!AT14,0) -> 0 | H54: ='Master Data'!AU14 -> 0
... A153: ='Master Data'!G113 -> ROZ23759 | B153: ='Master Data'!H113 -> Samuh Elaichi Rusk 65 g | C153: ='Master Data'!E113 -> Punjab | D153: ='Master Data'!F113 -> Rusk | E153: ='Master Data'!L113 -> 0 | F153: ='Master Data'!AS113 -> 0 | G153: =IFERROR('Master Data'!AT113,0) -> 0 | H153: ='Master Data'!AU113 -> 0

Sheet Plant-wise Tracker
A1: SAMUH — Plant-wise Production Tracker
A2: All plants in one view — grouped by plant with subtotal rows. Source: Master Data tab (live-linked).
A4: Merge Sku | B4: Merge Sku | C4: MM | D4: CMU Name | E4: Location | F4: Product Category | G4: SKU CODE | H4: Product Name | I4: MRP | J4: GM | K4: Case Size | L4: Month Plan in ton | M4: 46266 | N4: 46267 | O4: 46268 | P4: 46269 | Q4: 46270 | R4: 46271 | S4: 46272 | T4: 46273 | U4: 46274 | V4: 46275 | W4: 46276 | X4: 46277 | Y4: 46278 | Z4: 46279 | AA4: 46280 | AB4: 46281 | AC4: 46282 | AD4: 46283 | AE4: 46284 | AF4: 46285 | AG4: 46286 | AH4: 46287 | AI4: 46288 | AJ4: 46289 | AK4: 46290 | AL4: 46291 | AM4: 46292 | AN4: 46293 | AO4: 46294 | AP4: 46295 | AQ4: Total Production in Case in Case | AR4: Total Production in Ton In Ton | AS4: Achievement | AT4: Remaining Production in Ton
A5: Lucknow (CMU: VEETADAY INDUSTRIES PRIVATE LIMITED) — TOTAL | L5: =SUM(L6:L26) -> 0 | M5: =SUM(M6:M26) -> 0 | N5: =SUM(N6:N26) -> 0 | O5: =SUM(O6:O26) -> 0 | P5: =SUM(P6:P26) -> 0 | Q5: =SUM(Q6:Q26) -> 0 | R5: =SUM(R6:R26) -> 0 | S5: =SUM(S6:S26) -> 0 | ... AR5: =SUM(AR6:AR26) -> 0 | AS5: =IFERROR(AR5/L5,0) -> 0 | AT5: =SUM(AT6:AT26) -> 0
A6: ='Master Data'!A3 -> VEETADAY INDUSTRIES PRIVATE LIMITEDROZ39494 | B6: ='Master Data'!B3 -> VD | C6: ='Master Data'!C3 -> VDROZ39494 | D6: ='Master Data'!D3 -> VEETADAY INDUSTRIES PRIVATE LIMITED | E6: ='Master Data'!E3 -> Lucknow | F6: ='Master Data'!F3 -> Biscuits | G6: ='Master Data'!G3 -> ROZ39494 | H6: ='Master Data'!H3 -> Samuh Milky Biscuit 35 g | ... AP6: ='Master Data'!AP3 -> 0 | AQ6: =SUM(M6:AP6) -> 0 | AR6: =(AQ6*J6*K6)/1000000 -> 0 | AS6: =IFERROR(AR6/L6,0) -> 0 | AT6: =L6-AR6 -> 0
A7: ='Master Data'!A4 -> VEETADAY INDUSTRIES PRIVATE LIMITEDROZ23739 | B7: ='Master Data'!B4 -> VD | C7: ='Master Data'!C4 -> VDROZ23739 | D7: ='Master Data'!D4 -> VEETADAY INDUSTRIES PRIVATE LIMITED | E7: ='Master Data'!E4 -> Lucknow | F7: ='Master Data'!F4 -> Biscuits | G7: ='Master Data'!G4 -> ROZ23739 | H7: ='Master Data'!H4 -> Samuh Beat it! Bite it! Orange Cream Biscuit 35 g | ... AP7: ='Master Data'!AP4 -> 0 | AQ7: =SUM(M7:AP7) -> 0 | AR7: =(AQ7*J7*K7)/1000000 -> 0 | AS7: =IFERROR(AR7/L7,0) -> 0 | AT7: =L7-AR7 -> 0
A8: ='Master Data'!A5 -> VEETADAY INDUSTRIES PRIVATE LIMITEDROZ23738 | B8: ='Master Data'!B5 -> VD | C8: ='Master Data'!C5 -> VDROZ23738 | D8: ='Master Data'!D5 -> VEETADAY INDUSTRIES PRIVATE LIMITED | E8: ='Master Data'!E5 -> Lucknow | F8: ='Master Data'!F5 -> Biscuits | G8: ='Master Data'!G5 -> ROZ23738 | H8: ='Master Data'!H5 -> Samuh Beat it Bite it Chocolate Cream Biscuit 35 g | ... AP8: ='Master Data'!AP5 -> 0 | AQ8: =SUM(M8:AP8) -> 0 | AR8: =(AQ8*J8*K8)/1000000 -> 0 | AS8: =IFERROR(AR8/L8,0) -> 0 | AT8: =L8-AR8 -> 0
A9: ='Master Data'!A6 -> VEETADAY INDUSTRIES PRIVATE LIMITEDROZ23743 | B9: ='Master Data'!B6 -> VD | C9: ='Master Data'!C6 -> VDROZ23743 | D9: ='Master Data'!D6 -> VEETADAY INDUSTRIES PRIVATE LIMITED | E9: ='Master Data'!E6 -> Lucknow | F9: ='Master Data'!F6 -> Biscuits | G9: ='Master Data'!G6 -> ROZ23743 | H9: ='Master Data'!H6 -> Samuh Butter Cookies Biscuit 32 g | ... AP9: ='Master Data'!AP6 -> 0 | AQ9: =SUM(M9:AP9) -> 0 | AR9: =(AQ9*J9*K9)/1000000 -> 0 | AS9: =IFERROR(AR9/L9,0) -> 0 | AT9: =L9-AR9 -> 0
A10: ='Master Data'!A7 -> VEETADAY INDUSTRIES PRIVATE LIMITEDROZ23740 | B10: ='Master Data'!B7 -> VD | C10: ='Master Data'!C7 -> VDROZ23740 | D10: ='Master Data'!D7 -> VEETADAY INDUSTRIES PRIVATE LIMITED | E10: ='Master Data'!E7 -> Lucknow | F10: ='Master Data'!F7 -> Biscuits | G10: ='Master Data'!G7 -> ROZ23740 | H10: ='Master Data'!H7 -> Samuh Zeera Biscuit 35 g | ... AP10: ='Master Data'!AP7 -> 0 | AQ10: =SUM(M10:AP10) -> 0 | AR10: =(AQ10*J10*K10)/1000000 -> 0 | AS10: =IFERROR(AR10/L10,0) -> 0 | AT10: =L10-AR10 -> 0
A11: ='Master Data'!A8 -> VEETADAY INDUSTRIES PRIVATE LIMITEDROZ23741 | B11: ='Master Data'!B8 -> VD | C11: ='Master Data'!C8 -> VDROZ23741 | D11: ='Master Data'!D8 -> VEETADAY INDUSTRIES PRIVATE LIMITED | E11: ='Master Data'!E8 -> Lucknow | F11: ='Master Data'!F8 -> Biscuits | G11: ='Master Data'!G8 -> ROZ23741 | H11: ='Master Data'!H8 -> Samuh Coconut Cookies Biscuit 35 g | ... AP11: ='Master Data'!AP8 -> 0 | AQ11: =SUM(M11:AP11) -> 0 | AR11: =(AQ11*J11*K11)/1000000 -> 0 | AS11: =IFERROR(AR11/L11,0) -> 0 | AT11: =L11-AR11 -> 0
A12: ='Master Data'!A9 -> VEETADAY INDUSTRIES PRIVATE LIMITEDROZ23742 | B12: ='Master Data'!B9 -> VD | C12: ='Master Data'!C9 -> VDROZ23742 | D12: ='Master Data'!D9 -> VEETADAY INDUSTRIES PRIVATE LIMITED | E12: ='Master Data'!E9 -> Lucknow | F12: ='Master Data'!F9 -> Biscuits | G12: ='Master Data'!G9 -> ROZ23742 | H12: ='Master Data'!H9 -> Samuh Salty Sweety Biscuit 32 g | ... AP12: ='Master Data'!AP9 -> 0 | AQ12: =SUM(M12:AP12) -> 0 | AR12: =(AQ12*J12*K12)/1000000 -> 0 | AS12: =IFERROR(AR12/L12,0) -> 0 | AT12: =L12-AR12 -> 0
A13: ='Master Data'!A10 -> VEETADAY INDUSTRIES PRIVATE LIMITEDROZ36954 | B13: ='Master Data'!B10 -> VD | C13: ='Master Data'!C10 -> VDROZ36954 | D13: ='Master Data'!D10 -> VEETADAY INDUSTRIES PRIVATE LIMITED | E13: ='Master Data'!E10 -> Lucknow | F13: ='Master Data'!F10 -> Biscuits | G13: ='Master Data'!G10 -> ROZ36954 | H13: ='Master Data'!H10 -> Samuh Butter Cashew 30 g | ... AP13: ='Master Data'!AP10 -> 0 | AQ13: =SUM(M13:AP13) -> 0 | AR13: =(AQ13*J13*K13)/1000000 -> 0 | AS13: =IFERROR(AR13/L13,0) -> 0 | AT13: =L13-AR13 -> 0
A14: ='Master Data'!A11 -> VEETADAY INDUSTRIES PRIVATE LIMITEDROZ36955 | B14: ='Master Data'!B11 -> VD | C14: ='Master Data'!C11 -> VDROZ36955 | D14: ='Master Data'!D11 -> VEETADAY INDUSTRIES PRIVATE LIMITED | E14: ='Master Data'!E11 -> Lucknow | F14: ='Master Data'!F11 -> Biscuits | G14: ='Master Data'!G11 -> ROZ36955 | H14: ='Master Data'!H11 -> Samuh Beat it Bite it Chocolate Cream Biscuit 70 g | ... AP14: ='Master Data'!AP11 -> 0 | AQ14: =SUM(M14:AP14) -> 0 | AR14: =(AQ14*J14*K14)/1000000 -> 0 | AS14: =IFERROR(AR14/L14,0) -> 0 | AT14: =L14-AR14 -> 0
A15: ='Master Data'!A12 -> VEETADAY INDUSTRIES PRIVATE LIMITEDROZ36956 | B15: ='Master Data'!B12 -> VD | C15: ='Master Data'!C12 -> VDROZ36956 | D15: ='Master Data'!D12 -> VEETADAY INDUSTRIES PRIVATE LIMITED | E15: ='Master Data'!E12 -> Lucknow | F15: ='Master Data'!F12 -> Biscuits | G15: ='Master Data'!G12 -> ROZ36956 | H15: ='Master Data'!H12 -> Samuh Beat it! Bite it! Orange Cream Biscuit 70 g | ... AP15: ='Master Data'!AP12 -> 0 | AQ15: =SUM(M15:AP15) -> 0 | AR15: =(AQ15*J15*K15)/1000000 -> 0 | AS15: =IFERROR(AR15/L15,0) -> 0 | AT15: =L15-AR15 -> 0
A16: ='Master Data'!A13 -> VEETADAY INDUSTRIES PRIVATE LIMITEDROZ36957 | B16: ='Master Data'!B13 -> VD | C16: ='Master Data'!C13 -> VDROZ36957 | D16: ='Master Data'!D13 -> VEETADAY INDUSTRIES PRIVATE LIMITED | E16: ='Master Data'!E13 -> Lucknow | F16: ='Master Data'!F13 -> Biscuits | G16: ='Master Data'!G13 -> ROZ36957 | H16: ='Master Data'!H13 -> Samuh Coconut Cookies Biscuit 70g | ... AP16: ='Master Data'!AP13 -> 0 | AQ16: =SUM(M16:AP16) -> 0 | AR16: =(AQ16*J16*K16)/1000000 -> 0 | AS16: =IFERROR(AR16/L16,0) -> 0 | AT16: =L16-AR16 -> 0
A17: ='Master Data'!A14 -> VEETADAY INDUSTRIES PRIVATE LIMITEDROZ39495 | B17: ='Master Data'!B14 -> VD | C17: ='Master Data'!C14 -> VDROZ39495 | D17: ='Master Data'!D14 -> VEETADAY INDUSTRIES PRIVATE LIMITED | E17: ='Master Data'!E14 -> Lucknow | F17: ='Master Data'!F14 -> Biscuits | G17: ='Master Data'!G14 -> ROZ39495 | H17: ='Master Data'!H14 -> Samuh Milky Biscuit 70 g | ... AP17: ='Master Data'!AP14 -> 0 | AQ17: =SUM(M17:AP17) -> 0 | AR17: =(AQ17*J17*K17)/1000000 -> 0 | AS17: =IFERROR(AR17/L17,0) -> 0 | AT17: =L17-AR17 -> 0
... A26: ='Master Data'!A23 -> VEETADAY INDUSTRIES PRIVATE LIMITED1 | B26: ='Master Data'!B23 -> VD | C26: ='Master Data'!C23 -> VD1 | D26: ='Master Data'!D23 -> VEETADAY INDUSTRIES PRIVATE LIMITED | E26: ='Master Data'!E23 -> Lucknow | F26: ='Master Data'!F23 -> Biscuits | G26: ='Master Data'!G23 -> 1 | H26: ='Master Data'!H23 -> Marie 30 Rs | ... AP26: ='Master Data'!AP23 -> 0 | AQ26: =SUM(M26:AP26) -> 0 | AR26: =(AQ26*J26*K26)/1000000 -> 0 | AS26: =IFERROR(AR26/L26,0) -> 0 | AT26: =L26-AR26 -> 0
A27: Rudrapur (CMU: SWG) — TOTAL | L27: =SUM(L28:L48) -> 0 | M27: =SUM(M28:M48) -> 0 | N27: =SUM(N28:N48) -> 0 | O27: =SUM(O28:O48) -> 0 | P27: =SUM(P28:P48) -> 0 | Q27: =SUM(Q28:Q48) -> 0 | R27: =SUM(R28:R48) -> 0 | S27: =SUM(S28:S48) -> 0 | ... AR27: =SUM(AR28:AR48) -> 0 | AS27: =IFERROR(AR27/L27,0) -> 0 | AT27: =SUM(AT28:AT48) -> 0
A28: ='Master Data'!A24 -> SWGROZ39494 | B28: ='Master Data'!B24 -> SWG | C28: ='Master Data'!C24 -> SWGROZ39494 | D28: ='Master Data'!D24 -> SWG | E28: ='Master Data'!E24 -> Rudrapur | F28: ='Master Data'!F24 -> Biscuits | G28: ='Master Data'!G24 -> ROZ39494 | H28: ='Master Data'!H24 -> Samuh Milky Biscuit 35 g | ... AP28: ='Master Data'!AP24 -> 0 | AQ28: =SUM(M28:AP28) -> 0 | AR28: =(AQ28*J28*K28)/1000000 -> 0 | AS28: =IFERROR(AR28/L28,0) -> 0 | AT28: =L28-AR28 -> 0
A29: ='Master Data'!A25 -> SWGROZ23739 | B29: ='Master Data'!B25 -> SWG | C29: ='Master Data'!C25 -> SWGROZ23739 | D29: ='Master Data'!D25 -> SWG | E29: ='Master Data'!E25 -> Rudrapur | F29: ='Master Data'!F25 -> Biscuits | G29: ='Master Data'!G25 -> ROZ23739 | H29: ='Master Data'!H25 -> Samuh Beat it! Bite it! Orange Cream Biscuit 35 g | ... AP29: ='Master Data'!AP25 -> 0 | AQ29: =SUM(M29:AP29) -> 0 | AR29: =(AQ29*J29*K29)/1000000 -> 0 | AS29: =IFERROR(AR29/L29,0) -> 0 | AT29: =L29-AR29 -> 0
A30: ='Master Data'!A26 -> SWGROZ23738 | B30: ='Master Data'!B26 -> SWG | C30: ='Master Data'!C26 -> SWGROZ23738 | D30: ='Master Data'!D26 -> SWG | E30: ='Master Data'!E26 -> Rudrapur | F30: ='Master Data'!F26 -> Biscuits | G30: ='Master Data'!G26 -> ROZ23738 | H30: ='Master Data'!H26 -> Samuh Beat it Bite it Chocolate Cream Biscuit 35 g | ... AP30: ='Master Data'!AP26 -> 0 | AQ30: =SUM(M30:AP30) -> 0 | AR30: =(AQ30*J30*K30)/1000000 -> 0 | AS30: =IFERROR(AR30/L30,0) -> 0 | AT30: =L30-AR30 -> 0
A31: ='Master Data'!A27 -> SWGROZ23743 | B31: ='Master Data'!B27 -> SWG | C31: ='Master Data'!C27 -> SWGROZ23743 | D31: ='Master Data'!D27 -> SWG | E31: ='Master Data'!E27 -> Rudrapur | F31: ='Master Data'!F27 -> Biscuits | G31: ='Master Data'!G27 -> ROZ23743 | H31: ='Master Data'!H27 -> Samuh Butter Cookies Biscuit 32 g | ... AP31: ='Master Data'!AP27 -> 0 | AQ31: =SUM(M31:AP31) -> 0 | AR31: =(AQ31*J31*K31)/1000000 -> 0 | AS31: =IFERROR(AR31/L31,0) -> 0 | AT31: =L31-AR31 -> 0
A32: ='Master Data'!A28 -> SWGROZ23740 | B32: ='Master Data'!B28 -> SWG | C32: ='Master Data'!C28 -> SWGROZ23740 | D32: ='Master Data'!D28 -> SWG | E32: ='Master Data'!E28 -> Rudrapur | F32: ='Master Data'!F28 -> Biscuits | G32: ='Master Data'!G28 -> ROZ23740 | H32: ='Master Data'!H28 -> Samuh Zeera Biscuit 35 g | ... AP32: ='Master Data'!AP28 -> 0 | AQ32: =SUM(M32:AP32) -> 0 | AR32: =(AQ32*J32*K32)/1000000 -> 0 | AS32: =IFERROR(AR32/L32,0) -> 0 | AT32: =L32-AR32 -> 0
A33: ='Master Data'!A29 -> SWGROZ23741 | B33: ='Master Data'!B29 -> SWG | C33: ='Master Data'!C29 -> SWGROZ23741 | D33: ='Master Data'!D29 -> SWG | E33: ='Master Data'!E29 -> Rudrapur | F33: ='Master Data'!F29 -> Biscuits | G33: ='Master Data'!G29 -> ROZ23741 | H33: ='Master Data'!H29 -> Samuh Coconut Cookies Biscuit 35 g | ... AP33: ='Master Data'!AP29 -> 0 | AQ33: =SUM(M33:AP33) -> 0 | AR33: =(AQ33*J33*K33)/1000000 -> 0 | AS33: =IFERROR(AR33/L33,0) -> 0 | AT33: =L33-AR33 -> 0
A34: ='Master Data'!A30 -> SWGROZ23742 | B34: ='Master Data'!B30 -> SWG | C34: ='Master Data'!C30 -> SWGROZ23742 | D34: ='Master Data'!D30 -> SWG | E34: ='Master Data'!E30 -> Rudrapur | F34: ='Master Data'!F30 -> Biscuits | G34: ='Master Data'!G30 -> ROZ23742 | H34: ='Master Data'!H30 -> Samuh Salty Sweety Biscuit 32 g | ... AP34: ='Master Data'!AP30 -> 0 | AQ34: =SUM(M34:AP34) -> 0 | AR34: =(AQ34*J34*K34)/1000000 -> 0 | AS34: =IFERROR(AR34/L34,0) -> 0 | AT34: =L34-AR34 -> 0
A35: ='Master Data'!A31 -> SWGROZ36954 | B35: ='Master Data'!B31 -> SWG | C35: ='Master Data'!C31 -> SWGROZ36954 | D35: ='Master Data'!D31 -> SWG | E35: ='Master Data'!E31 -> Rudrapur | F35: ='Master Data'!F31 -> Biscuits | G35: ='Master Data'!G31 -> ROZ36954 | H35: ='Master Data'!H31 -> Samuh Butter Cashew 30 g | ... AP35: ='Master Data'!AP31 -> 0 | AQ35: =SUM(M35:AP35) -> 0 | AR35: =(AQ35*J35*K35)/1000000 -> 0 | AS35: =IFERROR(AR35/L35,0) -> 0 | AT35: =L35-AR35 -> 0
A36: ='Master Data'!A32 -> SWGROZ36955 | B36: ='Master Data'!B32 -> SWG | C36: ='Master Data'!C32 -> SWGROZ36955 | D36: ='Master Data'!D32 -> SWG | E36: ='Master Data'!E32 -> Rudrapur | F36: ='Master Data'!F32 -> Biscuits | G36: ='Master Data'!G32 -> ROZ36955 | H36: ='Master Data'!H32 -> Samuh Beat it Bite it Chocolate Cream Biscuit 70 g | ... AP36: ='Master Data'!AP32 -> 0 | AQ36: =SUM(M36:AP36) -> 0 | AR36: =(AQ36*J36*K36)/1000000 -> 0 | AS36: =IFERROR(AR36/L36,0) -> 0 | AT36: =L36-AR36 -> 0
A37: ='Master Data'!A33 -> SWGROZ36956 | B37: ='Master Data'!B33 -> SWG | C37: ='Master Data'!C33 -> SWGROZ36956 | D37: ='Master Data'!D33 -> SWG | E37: ='Master Data'!E33 -> Rudrapur | F37: ='Master Data'!F33 -> Biscuits | G37: ='Master Data'!G33 -> ROZ36956 | H37: ='Master Data'!H33 -> Samuh Beat it! Bite it! Orange Cream Biscuit 70 g | ... AP37: ='Master Data'!AP33 -> 0 | AQ37: =SUM(M37:AP37) -> 0 | AR37: =(AQ37*J37*K37)/1000000 -> 0 | AS37: =IFERROR(AR37/L37,0) -> 0 | AT37: =L37-AR37 -> 0
A38: ='Master Data'!A34 -> SWGROZ36957 | B38: ='Master Data'!B34 -> SWG | C38: ='Master Data'!C34 -> SWGROZ36957 | D38: ='Master Data'!D34 -> SWG | E38: ='Master Data'!E34 -> Rudrapur | F38: ='Master Data'!F34 -> Biscuits | G38: ='Master Data'!G34 -> ROZ36957 | H38: ='Master Data'!H34 -> Samuh Coconut Cookies Biscuit 70g | ... AP38: ='Master Data'!AP34 -> 0 | AQ38: =SUM(M38:AP38) -> 0 | AR38: =(AQ38*J38*K38)/1000000 -> 0 | AS38: =IFERROR(AR38/L38,0) -> 0 | AT38: =L38-AR38 -> 0
A39: ='Master Data'!A35 -> SWGROZ39495 | B39: ='Master Data'!B35 -> SWG | C39: ='Master Data'!C35 -> SWGROZ39495 | D39: ='Master Data'!D35 -> SWG | E39: ='Master Data'!E35 -> Rudrapur | F39: ='Master Data'!F35 -> Biscuits | G39: ='Master Data'!G35 -> ROZ39495 | H39: ='Master Data'!H35 -> Samuh Milky Biscuit 70 g | ... AP39: ='Master Data'!AP35 -> 0 | AQ39: =SUM(M39:AP39) -> 0 | AR39: =(AQ39*J39*K39)/1000000 -> 0 | AS39: =IFERROR(AR39/L39,0) -> 0 | AT39: =L39-AR39 -> 0
... A48: ='Master Data'!A44 -> SWG1 | B48: ='Master Data'!B44 -> SWG | C48: ='Master Data'!C44 -> SWG1 | D48: ='Master Data'!D44 -> SWG | E48: ='Master Data'!E44 -> Rudrapur | F48: ='Master Data'!F44 -> Biscuits | G48: ='Master Data'!G44 -> 1 | H48: ='Master Data'!H44 -> Marie 30 Rs | ... AP48: ='Master Data'!AP44 -> 0 | AQ48: =SUM(M48:AP48) -> 0 | AR48: =(AQ48*J48*K48)/1000000 -> 0 | AS48: =IFERROR(AR48/L48,0) -> 0 | AT48: =L48-AR48 -> 0
A49: Asansol, West Bengal (CMU: STRAIGHT LINE FOOD PRODUCTS PRIVATE LIMITED) — TOTAL | L49: =SUM(L50:L70) -> 0 | M49: =SUM(M50:M70) -> 0 | N49: =SUM(N50:N70) -> 0 | O49: =SUM(O50:O70) -> 0 | P49: =SUM(P50:P70) -> 0 | Q49: =SUM(Q50:Q70) -> 0 | R49: =SUM(R50:R70) -> 0 | S49: =SUM(S50:S70) -> 0 | ... AR49: =SUM(AR50:AR70) -> 0 | AS49: =IFERROR(AR49/L49,0) -> 0 | AT49: =SUM(AT50:AT70) -> 0
A50: ='Master Data'!A45 -> STRAIGHT LINE FOOD PRODUCTS PRIVATE LIMITEDROZ23738 | B50: ='Master Data'!B45 -> STR | C50: ='Master Data'!C45 -> STRROZ23738 | D50: ='Master Data'!D45 -> STRAIGHT LINE FOOD PRODUCTS PRIVATE LIMITED | E50: ='Master Data'!E45 -> Asansol, West Bengal | F50: ='Master Data'!F45 -> Biscuits | G50: ='Master Data'!G45 -> ROZ23738 | H50: ='Master Data'!H45 -> Samuh Beat it Bite it Chocolate Cream Biscuit 35 g | ... AP50: ='Master Data'!AP45 -> 0 | AQ50: =SUM(M50:AP50) -> 0 | AR50: =(AQ50*J50*K50)/1000000 -> 0 | AS50: =IFERROR(AR50/L50,0) -> 0 | AT50: =L50-AR50 -> 0
A51: ='Master Data'!A46 -> STRAIGHT LINE FOOD PRODUCTS PRIVATE LIMITEDROZ23739 | B51: ='Master Data'!B46 -> STR | C51: ='Master Data'!C46 -> STRROZ23739 | D51: ='Master Data'!D46 -> STRAIGHT LINE FOOD PRODUCTS PRIVATE LIMITED | E51: ='Master Data'!E46 -> Asansol, West Bengal | F51: ='Master Data'!F46 -> Biscuits | G51: ='Master Data'!G46 -> ROZ23739 | H51: ='Master Data'!H46 -> Samuh Beat it! Bite it! Orange Cream Biscuit 35 g | ... AP51: ='Master Data'!AP46 -> 0 | AQ51: =SUM(M51:AP51) -> 0 | AR51: =(AQ51*J51*K51)/1000000 -> 0 | AS51: =IFERROR(AR51/L51,0) -> 0 | AT51: =L51-AR51 -> 0
A52: ='Master Data'!A47 -> STRAIGHT LINE FOOD PRODUCTS PRIVATE LIMITEDROZ23741 | B52: ='Master Data'!B47 -> STR | C52: ='Master Data'!C47 -> STRROZ23741 | D52: ='Master Data'!D47 -> STRAIGHT LINE FOOD PRODUCTS PRIVATE LIMITED | E52: ='Master Data'!E47 -> Asansol, West Bengal | F52: ='Master Data'!F47 -> Biscuits | G52: ='Master Data'!G47 -> ROZ23741 | H52: ='Master Data'!H47 -> Samuh Coconut Cookies Biscuit 35 g | ... AP52: ='Master Data'!AP47 -> 0 | AQ52: =SUM(M52:AP52) -> 0 | AR52: =(AQ52*J52*K52)/1000000 -> 0 | AS52: =IFERROR(AR52/L52,0) -> 0 | AT52: =L52-AR52 -> 0
A53: ='Master Data'!A48 -> STRAIGHT LINE FOOD PRODUCTS PRIVATE LIMITEDROZ36954 | B53: ='Master Data'!B48 -> STR | C53: ='Master Data'!C48 -> STRROZ36954 | D53: ='Master Data'!D48 -> STRAIGHT LINE FOOD PRODUCTS PRIVATE LIMITED | E53: ='Master Data'!E48 -> Asansol, West Bengal | F53: ='Master Data'!F48 -> Biscuits | G53: ='Master Data'!G48 -> ROZ36954 | H53: ='Master Data'!H48 -> Samuh Butter Cashew 30 g | ... AP53: ='Master Data'!AP48 -> 0 | AQ53: =SUM(M53:AP53) -> 0 | AR53: =(AQ53*J53*K53)/1000000 -> 0 | AS53: =IFERROR(AR53/L53,0) -> 0 | AT53: =L53-AR53 -> 0
A54: ='Master Data'!A49 -> STRAIGHT LINE FOOD PRODUCTS PRIVATE LIMITEDROZ23743 | B54: ='Master Data'!B49 -> STR | C54: ='Master Data'!C49 -> STRROZ23743 | D54: ='Master Data'!D49 -> STRAIGHT LINE FOOD PRODUCTS PRIVATE LIMITED | E54: ='Master Data'!E49 -> Asansol, West Bengal | F54: ='Master Data'!F49 -> Biscuits | G54: ='Master Data'!G49 -> ROZ23743 | H54: ='Master Data'!H49 -> Samuh Butter Cookies Biscuit 32 g | ... AP54: ='Master Data'!AP49 -> 0 | AQ54: =SUM(M54:AP54) -> 0 | AR54: =(AQ54*J54*K54)/1000000 -> 0 | AS54: =IFERROR(AR54/L54,0) -> 0 | AT54: =L54-AR54 -> 0
A55: ='Master Data'!A50 -> STRAIGHT LINE FOOD PRODUCTS PRIVATE LIMITEDROZ36962 | B55: ='Master Data'!B50 -> STR | C55: ='Master Data'!C50 -> STRROZ36962 | D55: ='Master Data'!D50 -> STRAIGHT LINE FOOD PRODUCTS PRIVATE LIMITED | E55: ='Master Data'!E50 -> Asansol, West Bengal | F55: ='Master Data'!F50 -> Biscuits | G55: ='Master Data'!G50 -> ROZ36962 | H55: ='Master Data'!H50 -> Samuh Marie Biscuit 75g | ... AP55: ='Master Data'!AP50 -> 0 | AQ55: =SUM(M55:AP55) -> 0 | AR55: =(AQ55*J55*K55)/1000000 -> 0 | AS55: =IFERROR(AR55/L55,0) -> 0 | AT55: =L55-AR55 -> 0
A56: ='Master Data'!A51 -> STRAIGHT LINE FOOD PRODUCTS PRIVATE LIMITEDROZ36955 | B56: ='Master Data'!B51 -> STR | C56: ='Master Data'!C51 -> STRROZ36955 | D56: ='Master Data'!D51 -> STRAIGHT LINE FOOD PRODUCTS PRIVATE LIMITED | E56: ='Master Data'!E51 -> Asansol, West Bengal | F56: ='Master Data'!F51 -> Biscuits | G56: ='Master Data'!G51 -> ROZ36955 | H56: ='Master Data'!H51 -> Samuh Beat it Bite it Chocolate Cream Biscuit 70 g | ... AP56: ='Master Data'!AP51 -> 0 | AQ56: =SUM(M56:AP56) -> 0 | AR56: =(AQ56*J56*K56)/1000000 -> 0 | AS56: =IFERROR(AR56/L56,0) -> 0 | AT56: =L56-AR56 -> 0
A57: ='Master Data'!A52 -> STRAIGHT LINE FOOD PRODUCTS PRIVATE LIMITEDROZ36957 | B57: ='Master Data'!B52 -> STR | C57: ='Master Data'!C52 -> STRROZ36957 | D57: ='Master Data'!D52 -> STRAIGHT LINE FOOD PRODUCTS PRIVATE LIMITED | E57: ='Master Data'!E52 -> Asansol, West Bengal | F57: ='Master Data'!F52 -> Biscuits | G57: ='Master Data'!G52 -> ROZ36957 | H57: ='Master Data'!H52 -> Samuh Coconut Cookies Biscuit 70g | ... AP57: ='Master Data'!AP52 -> 0 | AQ57: =SUM(M57:AP57) -> 0 | AR57: =(AQ57*J57*K57)/1000000 -> 0 | AS57: =IFERROR(AR57/L57,0) -> 0 | AT57: =L57-AR57 -> 0
...

Sheet Master Data
L1: =SUBTOTAL(9,L3:L1048576) -> 0 | M1: =SUBTOTAL(9,M3:M1048576) -> 0 | N1: =SUBTOTAL(9,N3:N1048576) -> 0 | O1: =SUBTOTAL(9,O3:O1048576) -> 0 | P1: =SUBTOTAL(9,P3:P1048576) -> 0 | Q1: =SUBTOTAL(9,Q3:Q1048576) -> 0 | R1: =SUBTOTAL(9,R3:R1048576) -> 0 | S1: =SUBTOTAL(9,S3:S1048576) -> 0 | ... AP1: =SUBTOTAL(9,AP3:AP1048576) -> 0 | AR1: =SUBTOTAL(9,AR3:AR1048576) -> 0 | AS1: =SUBTOTAL(9,AS3:AS1048576) -> 0 | AT1: =AS1/L1 -> #DIV/0! | AU1: =SUBTOTAL(9,AU3:AU1048576) -> 0
A2: Merge Sku | B2: Merge Sku | C2: MM | D2: CMU Name | E2: Location | F2: Product Category | G2: SKU CODE | H2: Product Name | I2: MRP | J2: GM | K2: Case Size | L2: Month Plan in ton | M2: 46296 | N2: 46297 | O2: 46298 | P2: 46299 | Q2: 46300 | R2: 46301 | S2: 46302 | T2: 46303 | U2: 46304 | V2: 46305 | W2: 46306 | X2: 46307 | Y2: 46308 | Z2: 46309 | AA2: 46310 | AB2: 46311 | AC2: 46312 | AD2: 46313 | AE2: 46314 | AF2: 46315 | AG2: 46316 | AH2: 46317 | AI2: 46318 | AJ2: 46319 | AK2: 46320 | AL2: 46321 | AM2: 46322 | AN2: 46323 | AO2: 46324 | AP2: 46325 | AQ2: 46326 | AR2: Total Production in Case in Case | AS2: Total Production in Ton In Ton | AT2: Achievement | AU2: Remaining Production in Ton
A3: =D3&G3 -> VEETADAY INDUSTRIES PRIVATE LIMITEDROZ39494 | B3: VD | C3: =B3&G3 -> VDROZ39494 | D3: VEETADAY INDUSTRIES PRIVATE LIMITED | E3: Lucknow | F3: Biscuits | G3: ROZ39494 | H3: Samuh Milky Biscuit 35 g | I3: 5 | J3: 35 | K3: 144 | AR3: =SUM(M3:AP3) -> 0 | AS3: =(AR3*J3*K3)/1000000 -> 0 | AT3: =AS3/L3 -> #DIV/0! | AU3: =L3-AS3 -> 0
A4: =D4&G4 -> VEETADAY INDUSTRIES PRIVATE LIMITEDROZ23739 | B4: VD | C4: =B4&G4 -> VDROZ23739 | D4: VEETADAY INDUSTRIES PRIVATE LIMITED | E4: Lucknow | F4: Biscuits | G4: ROZ23739 | H4: Samuh Beat it! Bite it! Orange Cream Biscuit 35 g | I4: 5 | J4: 35 | K4: 144 | AR4: =SUM(M4:AP4) -> 0 | AS4: =(AR4*J4*K4)/1000000 -> 0 | AT4: =AS4/L4 -> #DIV/0! | AU4: =L4-AS4 -> 0
A5: =D5&G5 -> VEETADAY INDUSTRIES PRIVATE LIMITEDROZ23738 | B5: VD | C5: =B5&G5 -> VDROZ23738 | D5: VEETADAY INDUSTRIES PRIVATE LIMITED | E5: Lucknow | F5: Biscuits | G5: ROZ23738 | H5: Samuh Beat it Bite it Chocolate Cream Biscuit 35 g | I5: 5 | J5: 35 | K5: 144 | AR5: =SUM(M5:AP5) -> 0 | AS5: =(AR5*J5*K5)/1000000 -> 0 | AT5: =AS5/L5 -> #DIV/0! | AU5: =L5-AS5 -> 0
A6: =D6&G6 -> VEETADAY INDUSTRIES PRIVATE LIMITEDROZ23743 | B6: VD | C6: =B6&G6 -> VDROZ23743 | D6: VEETADAY INDUSTRIES PRIVATE LIMITED | E6: Lucknow | F6: Biscuits | G6: ROZ23743 | H6: Samuh Butter Cookies Biscuit 32 g | I6: 5 | J6: 32 | K6: 144 | AR6: =SUM(M6:AP6) -> 0 | AS6: =(AR6*J6*K6)/1000000 -> 0 | AT6: =AS6/L6 -> #DIV/0! | AU6: =L6-AS6 -> 0
A7: =D7&G7 -> VEETADAY INDUSTRIES PRIVATE LIMITEDROZ23740 | B7: VD | C7: =B7&G7 -> VDROZ23740 | D7: VEETADAY INDUSTRIES PRIVATE LIMITED | E7: Lucknow | F7: Biscuits | G7: ROZ23740 | H7: Samuh Zeera Biscuit 35 g | I7: 5 | J7: 35 | K7: 144 | AR7: =SUM(M7:AP7) -> 0 | AS7: =(AR7*J7*K7)/1000000 -> 0 | AT7: =AS7/L7 -> #DIV/0! | AU7: =L7-AS7 -> 0
A8: =D8&G8 -> VEETADAY INDUSTRIES PRIVATE LIMITEDROZ23741 | B8: VD | C8: =B8&G8 -> VDROZ23741 | D8: VEETADAY INDUSTRIES PRIVATE LIMITED | E8: Lucknow | F8: Biscuits | G8: ROZ23741 | H8: Samuh Coconut Cookies Biscuit 35 g | I8: 5 | J8: 35 | K8: 144 | AR8: =SUM(M8:AP8) -> 0 | AS8: =(AR8*J8*K8)/1000000 -> 0 | AT8: =AS8/L8 -> #DIV/0! | AU8: =L8-AS8 -> 0
A9: =D9&G9 -> VEETADAY INDUSTRIES PRIVATE LIMITEDROZ23742 | B9: VD | C9: =B9&G9 -> VDROZ23742 | D9: VEETADAY INDUSTRIES PRIVATE LIMITED | E9: Lucknow | F9: Biscuits | G9: ROZ23742 | H9: Samuh Salty Sweety Biscuit 32 g | I9: 5 | J9: 32 | K9: 144 | AR9: =SUM(M9:AP9) -> 0 | AS9: =(AR9*J9*K9)/1000000 -> 0 | AT9: =AS9/L9 -> #DIV/0! | AU9: =L9-AS9 -> 0
A10: =D10&G10 -> VEETADAY INDUSTRIES PRIVATE LIMITEDROZ36954 | B10: VD | C10: =B10&G10 -> VDROZ36954 | D10: VEETADAY INDUSTRIES PRIVATE LIMITED | E10: Lucknow | F10: Biscuits | G10: ROZ36954 | H10: Samuh Butter Cashew 30 g | I10: 5 | J10: 30 | K10: 144 | AR10: =SUM(M10:AP10) -> 0 | AS10: =(AR10*J10*K10)/1000000 -> 0 | AT10: =AS10/L10 -> #DIV/0! | AU10: =L10-AS10 -> 0
A11: =D11&G11 -> VEETADAY INDUSTRIES PRIVATE LIMITEDROZ36955 | B11: VD | C11: =B11&G11 -> VDROZ36955 | D11: VEETADAY INDUSTRIES PRIVATE LIMITED | E11: Lucknow | F11: Biscuits | G11: ROZ36955 | H11: Samuh Beat it Bite it Chocolate Cream Biscuit 70 g | I11: 10 | J11: 70 | K11: 60 | AR11: =SUM(M11:AP11) -> 0 | AS11: =(AR11*J11*K11)/1000000 -> 0 | AT11: =AS11/L11 -> #DIV/0! | AU11: =L11-AS11 -> 0
A12: =D12&G12 -> VEETADAY INDUSTRIES PRIVATE LIMITEDROZ36956 | B12: VD | C12: =B12&G12 -> VDROZ36956 | D12: VEETADAY INDUSTRIES PRIVATE LIMITED | E12: Lucknow | F12: Biscuits | G12: ROZ36956 | H12: Samuh Beat it! Bite it! Orange Cream Biscuit 70 g | I12: 10 | J12: 70 | K12: 60 | AR12: =SUM(M12:AP12) -> 0 | AS12: =(AR12*J12*K12)/1000000 -> 0 | AT12: =AS12/L12 -> #DIV/0! | AU12: =L12-AS12 -> 0
A13: =D13&G13 -> VEETADAY INDUSTRIES PRIVATE LIMITEDROZ36957 | B13: VD | C13: =B13&G13 -> VDROZ36957 | D13: VEETADAY INDUSTRIES PRIVATE LIMITED | E13: Lucknow | F13: Biscuits | G13: ROZ36957 | H13: Samuh Coconut Cookies Biscuit 70g | I13: 10 | J13: 70 | K13: 60 | AR13: =SUM(M13:AP13) -> 0 | AS13: =(AR13*J13*K13)/1000000 -> 0 | AT13: =AS13/L13 -> #DIV/0! | AU13: =L13-AS13 -> 0
A14: =D14&G14 -> VEETADAY INDUSTRIES PRIVATE LIMITEDROZ39495 | B14: VD | C14: =B14&G14 -> VDROZ39495 | D14: VEETADAY INDUSTRIES PRIVATE LIMITED | E14: Lucknow | F14: Biscuits | G14: ROZ39495 | H14: Samuh Milky Biscuit 70 g | I14: 10 | J14: 70 | K14: 72 | AR14: =SUM(M14:AP14) -> 0 | AS14: =(AR14*J14*K14)/1000000 -> 0 | AT14: =AS14/L14 -> #DIV/0! | AU14: =L14-AS14 -> 0
... A22: =D22&G22 -> VEETADAY INDUSTRIES PRIVATE LIMITEDROZ50020 | B22: VD | C22: =B22&G22 -> VDROZ50020 | D22: VEETADAY INDUSTRIES PRIVATE LIMITED | E22: Lucknow | F22: Biscuits | G22: ROZ50020 | H22: Samuh Marie Biscuit 35 g | I22: 5 | J22: 35 | K22: 144 | AR22: =SUM(M22:AP22) -> 0 | AS22: =(AR22*J22*K22)/1000000 -> 0 | AT22: =AS22/L22 -> #DIV/0! | AU22: =L22-AS22 -> 0
A23: =D23&G23 -> VEETADAY INDUSTRIES PRIVATE LIMITED1 | B23: VD | C23: =B23&G23 -> VD1 | D23: VEETADAY INDUSTRIES PRIVATE LIMITED | E23: Lucknow | F23: Biscuits | G23: 1 | H23: Marie 30 Rs | I23: 30 | J23: 140 | K23: 40 | AR23: =SUM(M23:AP23) -> 0 | AS23: =(AR23*J23*K23)/1000000 -> 0 | AT23: =AS23/L23 -> #DIV/0! | AU23: =L23-AS23 -> 0
A24: =D24&G24 -> SWGROZ39494 | B24: SWG | C24: =B24&G24 -> SWGROZ39494 | D24: SWG | E24: Rudrapur | F24: Biscuits | G24: ROZ39494 | H24: Samuh Milky Biscuit 35 g | I24: 5 | J24: 35 | K24: 144 | AR24: =SUM(M24:AP24) -> 0 | AS24: =(AR24*J24*K24)/1000000 -> 0 | AT24: =AS24/L24 -> #DIV/0! | AU24: =L24-AS24 -> 0
A25: =D25&G25 -> SWGROZ23739 | B25: SWG | C25: =B25&G25 -> SWGROZ23739 | D25: SWG | E25: Rudrapur | F25: Biscuits | G25: ROZ23739 | H25: Samuh Beat it! Bite it! Orange Cream Biscuit 35 g | I25: 5 | J25: 35 | K25: 144 | AR25: =SUM(M25:AP25) -> 0 | AS25: =(AR25*J25*K25)/1000000 -> 0 | AT25: =AS25/L25 -> #DIV/0! | AU25: =L25-AS25 -> 0
A26: =D26&G26 -> SWGROZ23738 | B26: SWG | C26: =B26&G26 -> SWGROZ23738 | D26: SWG | E26: Rudrapur | F26: Biscuits | G26: ROZ23738 | H26: Samuh Beat it Bite it Chocolate Cream Biscuit 35 g | I26: 5 | J26: 35 | K26: 144 | AR26: =SUM(M26:AP26) -> 0 | AS26: =(AR26*J26*K26)/1000000 -> 0 | AT26: =AS26/L26 -> #DIV/0! | AU26: =L26-AS26 -> 0
A27: =D27&G27 -> SWGROZ23743 | B27: SWG | C27: =B27&G27 -> SWGROZ23743 | D27: SWG | E27: Rudrapur | F27: Biscuits | G27: ROZ23743 | H27: Samuh Butter Cookies Biscuit 32 g | I27: 5 | J27: 32 | K27: 144 | AR27: =SUM(M27:AP27) -> 0 | AS27: =(AR27*J27*K27)/1000000 -> 0 | AT27: =AS27/L27 -> #DIV/0! | AU27: =L27-AS27 -> 0
A28: =D28&G28 -> SWGROZ23740 | B28: SWG | C28: =B28&G28 -> SWGROZ23740 | D28: SWG | E28: Rudrapur | F28: Biscuits | G28: ROZ23740 | H28: Samuh Zeera Biscuit 35 g | I28: 5 | J28: 35 | K28: 144 | AR28: =SUM(M28:AP28) -> 0 | AS28: =(AR28*J28*K28)/1000000 -> 0 | AT28: =AS28/L28 -> #DIV/0! | AU28: =L28-AS28 -> 0
A29: =D29&G29 -> SWGROZ23741 | B29: SWG | C29: =B29&G29 -> SWGROZ23741 | D29: SWG | E29: Rudrapur | F29: Biscuits | G29: ROZ23741 | H29: Samuh Coconut Cookies Biscuit 35 g | I29: 5 | J29: 35 | K29: 144 | AR29: =SUM(M29:AP29) -> 0 | AS29: =(AR29*J29*K29)/1000000 -> 0 | AT29: =AS29/L29 -> #DIV/0! | AU29: =L29-AS29 -> 0
A30: =D30&G30 -> SWGROZ23742 | B30: SWG | C30: =B30&G30 -> SWGROZ23742 | D30: SWG | E30: Rudrapur | F30: Biscuits | G30: ROZ23742 | H30: Samuh Salty Sweety Biscuit 32 g | I30: 5 | J30: 32 | K30: 144 | AR30: =SUM(M30:AP30) -> 0 | AS30: =(AR30*J30*K30)/1000000 -> 0 | AT30: =AS30/L30 -> #DIV/0! | AU30: =L30-AS30 -> 0
A31: =D31&G31 -> SWGROZ36954 | B31: SWG | C31: =B31&G31 -> SWGROZ36954 | D31: SWG | E31: Rudrapur | F31: Biscuits | G31: ROZ36954 | H31: Samuh Butter Cashew 30 g | I31: 5 | J31: 30 | K31: 144 | AR31: =SUM(M31:AP31) -> 0 | AS31: =(AR31*J31*K31)/1000000 -> 0 | AT31: =AS31/L31 -> #DIV/0! | AU31: =L31-AS31 -> 0
A32: =D32&G32 -> SWGROZ36955 | B32: SWG | C32: =B32&G32 -> SWGROZ36955 | D32: SWG | E32: Rudrapur | F32: Biscuits | G32: ROZ36955 | H32: Samuh Beat it Bite it Chocolate Cream Biscuit 70 g | I32: 10 | J32: 70 | K32: 60 | AR32: =SUM(M32:AP32) -> 0 | AS32: =(AR32*J32*K32)/1000000 -> 0 | AT32: =AS32/L32 -> #DIV/0! | AU32: =L32-AS32 -> 0
A33: =D33&G33 -> SWGROZ36956 | B33: SWG | C33: =B33&G33 -> SWGROZ36956 | D33: SWG | E33: Rudrapur | F33: Biscuits | G33: ROZ36956 | H33: Samuh Beat it! Bite it! Orange Cream Biscuit 70 g | I33: 10 | J33: 70 | K33: 60 | AR33: =SUM(M33:AP33) -> 0 | AS33: =(AR33*J33*K33)/1000000 -> 0 | AT33: =AS33/L33 -> #DIV/0! | AU33: =L33-AS33 -> 0
A34: =D34&G34 -> SWGROZ36957 | B34: SWG | C34: =B34&G34 -> SWGROZ36957 | D34: SWG | E34: Rudrapur | F34: Biscuits | G34: ROZ36957 | H34: Samuh Coconut Cookies Biscuit 70g | I34: 10 | J34: 70 | K34: 60 | AR34: =SUM(M34:AP34) -> 0 | AS34: =(AR34*J34*K34)/1000000 -> 0 | AT34: =AS34/L34 -> #DIV/0! | AU34: =L34-AS34 -> 0
A35: =D35&G35 -> SWGROZ39495 | B35: SWG | C35: =B35&G35 -> SWGROZ39495 | D35: SWG | E35: Rudrapur | F35: Biscuits | G35: ROZ39495 | H35: Samuh Milky Biscuit 70 g | I35: 10 | J35: 70 | K35: 72 | AR35: =SUM(M35:AP35) -> 0 | AS35: =(AR35*J35*K35)/1000000 -> 0 | AT35: =AS35/L35 -> #DIV/0! | AU35: =L35-AS35 -> 0
... A43: =D43&G43 -> SWGROZ50020 | B43: SWG | C43: =B43&G43 -> SWGROZ50020 | D43: SWG | E43: Rudrapur | F43: Biscuits | G43: ROZ50020 | H43: Samuh Marie Biscuit 35 g | I43: 5 | J43: 35 | K43: 144 | AR43: =SUM(M43:AP43) -> 0 | AS43: =(AR43*J43*K43)/1000000 -> 0 | AT43: =AS43/L43 -> #DIV/0! | AU43: =L43-AS43 -> 0
A44: =D44&G44 -> SWG1 | B44: SWG | C44: =B44&G44 -> SWG1 | D44: SWG | E44: Rudrapur | F44: Biscuits | G44: 1 | H44: Marie 30 Rs | I44: 30 | J44: 140 | K44: 40 | AR44: =SUM(M44:AP44) -> 0 | AS44: =(AR44*J44*K44)/1000000 -> 0 | AT44: =AS44/L44 -> #DIV/0! | AU44: =L44-AS44 -> 0
A45: =D45&G45 -> STRAIGHT LINE FOOD PRODUCTS PRIVATE LIMITEDROZ23738 | B45: STR | C45: =B45&G45 -> STRROZ23738 | D45: STRAIGHT LINE FOOD PRODUCTS PRIVATE LIMITED | E45: Asansol, West Bengal | F45: Biscuits | G45: ROZ23738 | H45: Samuh Beat it Bite it Chocolate Cream Biscuit 35 g | I45: 5 | J45: 35 | K45: 144 | AR45: =SUM(M45:AP45) -> 0 | AS45: =(AR45*J45*K45)/1000000 -> 0 | AT45: =AS45/L45 -> #DIV/0! | AU45: =L45-AS45 -> 0
A46: =D46&G46 -> STRAIGHT LINE FOOD PRODUCTS PRIVATE LIMITEDROZ23739 | B46: STR | C46: =B46&G46 -> STRROZ23739 | D46: STRAIGHT LINE FOOD PRODUCTS PRIVATE LIMITED | E46: Asansol, West Bengal | F46: Biscuits | G46: ROZ23739 | H46: Samuh Beat it! Bite it! Orange Cream Biscuit 35 g | I46: 5 | J46: 35 | K46: 144 | AR46: =SUM(M46:AP46) -> 0 | AS46: =(AR46*J46*K46)/1000000 -> 0 | AT46: =AS46/L46 -> #DIV/0! | AU46: =L46-AS46 -> 0
A47: =D47&G47 -> STRAIGHT LINE FOOD PRODUCTS PRIVATE LIMITEDROZ23741 | B47: STR | C47: =B47&G47 -> STRROZ23741 | D47: STRAIGHT LINE FOOD PRODUCTS PRIVATE LIMITED | E47: Asansol, West Bengal | F47: Biscuits | G47: ROZ23741 | H47: Samuh Coconut Cookies Biscuit 35 g | I47: 5 | J47: 35 | K47: 144 | AR47: =SUM(M47:AP47) -> 0 | AS47: =(AR47*J47*K47)/1000000 -> 0 | AT47: =AS47/L47 -> #DIV/0! | AU47: =L47-AS47 -> 0
A48: =D48&G48 -> STRAIGHT LINE FOOD PRODUCTS PRIVATE LIMITEDROZ36954 | B48: STR | C48: =B48&G48 -> STRROZ36954 | D48: STRAIGHT LINE FOOD PRODUCTS PRIVATE LIMITED | E48: Asansol, West Bengal | F48: Biscuits | G48: ROZ36954 | H48: Samuh Butter Cashew 30 g | I48: 5 | J48: 30 | K48: 144 | AR48: =SUM(M48:AP48) -> 0 | AS48: =(AR48*J48*K48)/1000000 -> 0 | AT48: =AS48/L48 -> #DIV/0! | AU48: =L48-AS48 -> 0
A49: =D49&G49 -> STRAIGHT LINE FOOD PRODUCTS PRIVATE LIMITEDROZ23743 | B49: STR | C49: =B49&G49 -> STRROZ23743 | D49: STRAIGHT LINE FOOD PRODUCTS PRIVATE LIMITED | E49: Asansol, West Bengal | F49: Biscuits | G49: ROZ23743 | H49: Samuh Butter Cookies Biscuit 32 g | I49: 5 | J49: 32 | K49: 144 | AR49: =SUM(M49:AP49) -> 0 | AS49: =(AR49*J49*K49)/1000000 -> 0 | AT49: =AS49/L49 -> #DIV/0! | AU49: =L49-AS49 -> 0
A50: =D50&G50 -> STRAIGHT LINE FOOD PRODUCTS PRIVATE LIMITEDROZ36962 | B50: STR | C50: =B50&G50 -> STRROZ36962 | D50: STRAIGHT LINE FOOD PRODUCTS PRIVATE LIMITED | E50: Asansol, West Bengal | F50: Biscuits | G50: ROZ36962 | H50: Samuh Marie Biscuit 75g | I50: 10 | J50: 75 | K50: 72 | AR50: =SUM(M50:AP50) -> 0 | AS50: =(AR50*J50*K50)/1000000 -> 0 | AT50: =AS50/L50 -> #DIV/0! | AU50: =L50-AS50 -> 0
A51: =D51&G51 -> STRAIGHT LINE FOOD PRODUCTS PRIVATE LIMITEDROZ36955 | B51: STR | C51: =B51&G51 -> STRROZ36955 | D51: STRAIGHT LINE FOOD PRODUCTS PRIVATE LIMITED | E51: Asansol, West Bengal | F51: Biscuits | G51: ROZ36955 | H51: Samuh Beat it Bite it Chocolate Cream Biscuit 70 g | I51: 10 | J51: 70 | K51: 60 | AR51: =SUM(M51:AP51) -> 0 | AS51: =(AR51*J51*K51)/1000000 -> 0 | AT51: =AS51/L51 -> #DIV/0! | AU51: =L51-AS51 -> 0
A52: =D52&G52 -> STRAIGHT LINE FOOD PRODUCTS PRIVATE LIMITEDROZ36957 | B52: STR | C52: =B52&G52 -> STRROZ36957 | D52: STRAIGHT LINE FOOD PRODUCTS PRIVATE LIMITED | E52: Asansol, West Bengal | F52: Biscuits | G52: ROZ36957 | H52: Samuh Coconut Cookies Biscuit 70g | I52: 10 | J52: 70 | K52: 60 | AR52: =SUM(M52:AP52) -> 0 | AS52: =(AR52*J52*K52)/1000000 -> 0 | AT52: =AS52/L52 -> #DIV/0! | AU52: =L52-AS52 -> 0
A53: =D53&G53 -> STRAIGHT LINE FOOD PRODUCTS PRIVATE LIMITEDROZ36959 | B53: STR | C53: =B53&G53 -> STRROZ36959 | D53: STRAIGHT LINE FOOD PRODUCTS PRIVATE LIMITED | E53: Asansol, West Bengal | F53: Biscuits | G53: ROZ36959 | H53: Samuh Salty Sweety Biscuit 65 g | I53: 10 | J53: 65 | K53: 60 | AR53: =SUM(M53:AP53) -> 0 | AS53: =(AR53*J53*K53)/1000000 -> 0 | AT53: =AS53/L53 -> #DIV/0! | AU53: =L53-AS53 -> 0
A54: =D54&G54 -> STRAIGHT LINE FOOD PRODUCTS PRIVATE LIMITEDROZ23742 | B54: STR | C54: =B54&G54 -> STRROZ23742 | D54: STRAIGHT LINE FOOD PRODUCTS PRIVATE LIMITED | E54: Asansol, West Bengal | F54: Biscuits | G54: ROZ23742 | H54: Samuh Salty Sweety Biscuit 32 g | I54: 5 | J54: 32 | K54: 144 | AR54: =SUM(M54:AP54) -> 0 | AS54: =(AR54*J54*K54)/1000000 -> 0 | AT54: =AS54/L54 -> #DIV/0! | AU54: =L54-AS54 -> 0
...
